Workbook

Sheet pc list 140318
A1: nu_pers_num | B1: Name | C1: Grade | D1: machine_code | E1: dept_name | F1: system_name | G1: model_name | H1: location | I1: make | J1: ch_remarks
A2: 20114 | B2: KANUBHAI K DESAI | C2: E0 | D2: PCC142 | E2: PURCHASE | F2: CORE SERIES TFT | G2: HP ELITE 8200 | H2: SM/CM COMM OFFICE | I2: HP
A3: 20205 | B3: HEMANT K CHAWLA | C3: E0 | D3: ATC048 | E3: HR-ADMINISTRATION | F3: CORE SERIES TFT | G3: HP ELITE 8200 | H3: SM/CM HR OFFICE | I3: HP
A4: 20350 | B4: KANTILAL S PATEL | C4: F1 | D4: MSC325 | E4: HR-ADMINISTRATION | F4: CORE SERIES TFT | G4: HCL INFINITI A390 TRU | H4: CM/SM OFFICE | I4: HCL
A5: 20360 | B5: JANAK KUMAR A A PATEL | C5: F0 | D5: TEC007 | E5: MECH-W/S | F5: CORE SERIES TFT | G5: HCL INFINITI A390 TRU | H5: AUTO W/S | I5: HCL
A6: 20394 | B6: MAHESH P SOMANI | C6: F1 | D6: PGC044 | E6: CIVIL | F6: CORE SERIES TFT | G6: HP DX2480 | H6: MAINTENANCE BLOCK | I6: HP
A7: 20489 | B7: JAYESH KUMAR B SANGHAVI | C7: F0 | D7: FAC184 | E7: FINANCE & ACCOUNTS | F7: CORE SERIES TFT | G7: HCL INFINITI A390 TRU | H7: SM/CM F&A OFFICE | I7: HCL
A8: 20491 | B8: DINUBHAI U PANCHAL | C8: F0 | D8: ADC166 | E8: HR-ADMINISTRATION | F8: CORE SERIES TFT | G8: HCL INFINITI A390 TRU | H8: SM/CM HR OFFICE | I8: HCL
A9: 20495 | B9: K SIVADASAN NAIR | C9: G0 | D9: V1C026 | E9: MECH-W/S | F9: CORE SERIES TFT | G9: ACER VERITON Q170 | H9: AUTO W/S | I9: ACER
A10: 20505 | B10: VENKATESVARULU C | C10: D0 | D10: ELC061 | E10: ELECTRICAL | F10: CORE SERIES TFT | G10: HP ELITE 800G2 | H10: AGM/GM (ELECTRICAL) OFFICE | I10: HP
A11: 20506 | B11: RAJESH M CHOPDE | C11: C0 | D11: PRC074 | E11: PROCESS GROUP | F11: CORE SERIES TFT | G11: HP ELITE 800G1 | H11: SM/CM (PROCESS) | I11: HP
A12: 20551 | B12: RAJESH KUMAR AGARWAL | C12: F1 | D12: FAC182 | E12: FINANCE & ACCOUNTS | F12: CORE SERIES TFT | G12: HCL INFINITI A390 TRU | H12: SM/CM F&A OFFICE | I12: HCL
A13: 20559 | B13: SUDHIR V VASWANI | C13: F1 | D13: EMC001 | E13: ELECT.MAINT. T/SHIP | F13: CORE SERIES TFT | G13: HP ELITE 8200 | H13: ESTATE OFFICE | I13: HP
... A19: 20652 | B19: MANI R SHARMA | C19: C0 | D19: PGC058 | E19: PRODUCTION | F19: CORE SERIES TFT | G19: HP ELITE 800G1 | H19: GM(PRODN.) OFFICE | I19: HP
A20: 20696 | B20: D B SHAH | D20: LBC040 | E20: CHEMICAL LABORATORY | F20: CORE SERIES TFT | G20: ACER VERITON M-200 H57 | H20: LAB OFFICE | I20: ACER
A21: 20704 | B21: MANHARBHAI R PATEL | C21: F0 | D21: IUC038 | E21: INSTRUMENT-UREA | F21: CORE SERIES TFT | G21: HP ELITE 8200 | H21: UREA | I21: HP
A22: 20709 | B22: HEMANT G PATEL | C22: F1 | D22: MSC326 | E22: HR-ADMINISTRATION | F22: CORE SERIES TFT | G22: HCL INFINITI A390 TRU | H22: SM/CM HR OFFICE | I22: HCL
A23: 20740 | B23: ARVINDKUMAR V MODI | C23: F0 | D23: ADC157 | E23: HR-ADMINISTRATION | F23: CORE SERIES TFT | G23: ACER VERITON M-200 H57 | H23: VIGILENCE OFFICE | I23: ACER
A24: 20743 | B24: BAKULKUMAR C MISTRY | C24: E0 | D24: SPC041 | E24: FINANCE & ACCOUNTS | F24: CORE SERIES TFT | G24: ACER VERITON M-200 H57 | H24: SM/CM F&A OFFICE | I24: ACER
A25: 20751 | B25: CHAMPAKBHAI B PATEL | C25: F1 | D25: V1C025 | E25: MPC-DRAWING SECTION | F25: CORE SERIES TFT | G25: ACER VERITON Q170 | H25: DRAWING OFFICE | I25: ACER
A26: 20767 | B26: ANAND KISHOR SHARMA | C26: E0 | D26: LBC051 | E26: CHEMICAL LABORATORY | F26: CORE SERIES TFT | G26: HP ELITE 8200 | H26: LAB OFFICE | I26: HP
A27: 20768 | B27: S G HARSHE | D27: TRC061 | E27: TRANSPORTATION | F27: CORE SERIES TFT | G27: HCL INFINITI A390 TRU | H27: TPTN OFFICE | I27: HCL
A28: 20799 | B28: JITENDRA G TRIVEDI | C28: E0 | D28: V1C014 | E28: PRODN-OFFSITE | F28: CORE SERIES TFT | G28: ACER VERITON Q170 | H28: OFFSITE OFFICE | I28: ACER
A29: 20817 | B29: NARENDRAKUMAR D PRAJAPATI | C29: F0 | D29: IUC037 | E29: INSTRUMENT-UREA | F29: CORE SERIES TFT | G29: HP ELITE 8200 | H29: UREA | I29: HP
A30: 20818 | B30: ROHITKUMAR K UPADHYAY | C30: F0 | D30: IWC046 | E30: INSTRUMENT-PHP | F30: CORE SERIES TFT | G30: ACER VERITON M-200 H57 | H30: PHP | I30: ACER
A31: 20820 | B31: BASWARAJ C NANDI | C31: F0 | D31: TCC080 | E31: INSTRUMENT-POWER | F31: CORE SERIES TFT | G31: HP DX2480 | H31: POWER | I31: HP
A32: 20827 | B32: KAUSHIK D PRAJAPATI | C32: F1 | D32: MWC028 | E32: MECH-W/S | F32: CORE SERIES CRT | G32: WIPRO SUPER GENIOUS | H32: W/S | I32: WIPRO
A33: 20832 | B33: RATILAL C LAD | C33: F1 | D33: IAC032 | E33: INSTRUMENT-AMMONIA | F33: CORE SERIES TFT | G33: HP ELITE 8200 | H33: INST-AMM-2 | I33: HP | J33: na suthar
A34: 20834 | B34: ISHWAR BHAI J PARMAR | C34: F1 | D34: MPC016 | E34: MECH-POWER | F34: CORE SERIES TFT | G34: HP ELITE 800G2 | H34: POWER PLANT | I34: HP
A35: 20852 | B35: BIPINCHANDRA J JOSHI | C35: F1 | D35: CEC002 | E35: ELECTRICAL-UREA | F35: CORE SERIES TFT | G35: HCL INFINITI A390 TRU | H35: UREA - I | I35: HCL
A36: 20853 | B36: KANAIYALAL L PATEL | C36: F0 | D36: EPC017 | E36: ELECTRICAL-POWER | F36: CORE SERIES TFT | G36: HCL INFINITI A390 TRU | H36: POWER PLANT | I36: HCL
A37: 20855 | B37: CHANDUBHAI G PATEL | C37: F0 | D37: ELC059 | E37: ELECTRICAL | F37: CORE SERIES TFT | G37: HP ELITE 8200 | H37: MAINT BLOCK | I37: HP
A38: 20857 | B38: CHATURBHAI K VASAVA | C38: F0 | D38: ODC026 | E38: ELECTRICAL-AMMONIA | F38: CORE SERIES TFT | G38: HP DX2480 | H38: PGR | I38: HP
A39: 20858 | B39: NANUBHAI P TANDEL | C39: F0 | D39: EBC018 | E39: ELECTRICAL-PHP | F39: CORE SERIES TFT | G39: HCL INFINITI A390 TRU | H39: PHP | I39: HCL
A40: 20859 | B40: AJAYKUMAR I DAVE | C40: E0 | D40: MBC019 | E40: MECH-PHP | F40: CORE SERIES TFT | G40: HP ELITE 8200 | H40: PHP | I40: HP
A41: 20860 | B41: SANJAY KUMAR H NANAVATI | C41: E0 | D41: EUC012 | E41: MECH-OFFSITE | F41: CORE SERIES TFT | G41: HP ELITE 8200 | H41: OFFSITE-I | I41: HP | J41: dilip dhabarde
A42: 20861 | B42: ARUNKUMAR I DESAI | C42: E0 | D42: TRC068 | E42: MECH-PHP | F42: CORE SERIES TFT | G42: HP ELITE 800G2 | H42: PHP OFFICE FIRST FLOOR | I42: HP
A43: 20862 | B43: DIPAK A NAIK | C43: F0 | D43: NDC028 | E43: NDT LABORATORY | F43: CORE SERIES TFT | G43: HP ELITE 8200 | H43: NDT | I43: HP
A44: 20864 | B44: SURESH T BHAMBHANI | C44: F0 | D44: MUC044 | E44: MECH-POWER | F44: CORE SERIES TFT | G44: HP ELITE 8200 | H44: POWER | I44: HP
A45: 20865 | B45: KIRAN K SHAH | C45: F0 | D45: MBC017 | E45: MECH-W/S | F45: CORE SERIES TFT | G45: ACER VERITON M-200 H57 | H45: W/S | I45: ACER
...

Sheet Sheet1
A1: select a.machine_code, a.dept_code, b.dept_name, a.nu_pers_num,a.device_code, a.system_name,
A2: a.model_name, a.location, a.make, a.ch_remarks
A3: from TB_HARDWARE_MASTER_HEADER a, tb_dept b
A4: where
A5: a.dept_code = b.dept_code and
A6: a.KRIBHCO_HARDWARE = 'Y' and
A7: a.deleted <> 'Y'and
A8: a.DEVICE_CODE = 'C' and
A9: (a.stat = 'A' or a.stat = 'W')
A10: ;

Sheet Emp List
A1: Per. No. | B1: Name | C1: Emp SubGroup
A2: 20029 | B2: RAGHUNATHSINGH RAGHAV | C2: H0
A3: 20114 | B3: KANUBHAI K DESAI | C3: E0
A4: 20137 | B4: SUDHAKAR N PATIL | C4: G0
A5: 20165 | B5: DATTATRAY B KADAM | C5: G1
A6: 20172 | B6: PARBHUBHAI V PATEL | C6: G0
A7: 20173 | B7: NATVARBHAI K PATEL | C7: J0
A8: 20174 | B8: DINESHBHAI C PATEL | C8: G1
A9: 20175 | B9: DINESHBHAI K PATEL | C9: H1
A10: 20178 | B10: ARVINDBHAI M PATEL | C10: I0
A11: 20179 | B11: ISHWARBHAI F PATEL | C11: I0
A12: 20180 | B12: BHIKHUBHAI K PATEL | C12: H0
A13: 20183 | B13: KANTILAL N PATEL | C13: H0
... A1065: 23531 | B1065: DEEPAK RAVINDRABHAI KHATRI | C1065: L1
A1066: 23532 | B1066: ANKUSHBHAI DHAGJIBHAI CHAUDHARI | C1066: 72
A1067: 23533 | B1067: UJJAVALKUMAR DINESHBHAI SHRIMALI | C1067: L1
A1068: 23534 | B1068: MRUGESH SUNILKUMAR PAREKH | C1068: L1
A1069: 23537 | B1069: PRAMOD KUMAR YADAV | C1069: K0
A1070: 23538 | B1070: DIPAKKUMAR MANILAL LAD | C1070: K0
A1071: 23539 | B1071: BHAVESH MAGANBHAI RATHOD | C1071: L1
A1072: 23540 | B1072: TEJAL GOKUL PATIL | C1072: L1
A1073: 23541 | B1073: PRAKASH BALVANTBHAI PATEL | C1073: P0
A1074: 23542 | B1074: DIVYESH CHAMPAKBHAI PATEL | C1074: P0
A1075: 23543 | B1075: NITESH SINGH CHOUHAN | C1075: 72
A1076: 23544 | B1076: DHRUVIL ARJUNBHAI DABHI | C1076: 72
A1077: 23545 | B1077: NAYANKUMAR DEVENDRAKUMAR KATHAWALA | C1077: L0
A1078: 23546 | B1078: SHEENA JOHNSON | C1078: L0
A1079: 23547 | B1079: VISHWA DILIPBHAI BARBHAYA | C1079: L0
A1080: 23548 | B1080: HARKISHAN HIMMATBHAI GHODADARA | C1080: L0
A1081: 23582 | B1081: SHAILESH BHAILALBHAI PATEL | C1081: I0
A1082: 23586 | B1082: RAJESHKUMAR ASHOKBHAI CHUNARA | C1082: 72
A1083: 23587 | B1083: SURAJSINH SAGUJI RAJPUT | C1083: 72
A1084: 23598 | B1084: RITESH PRALHADRAO BAWNER | C1084: G1
A1085: 23602 | B1085: TANUJ BAKSHI | C1085: G1
A1086: 23605 | B1086: MANMOHAN JHA | C1086: 71
A1087: 23607 | B1087: KEERTI SHUKLA | C1087: 71
A1088: 23611 | B1088: VISHAL SINGH | C1088: 72
A1089: 23612 | B1089: MANOJ KUMAR | C1089: 72
A1090: 23613 | B1090: VIRENDRA JADAN | C1090: 72
A1091: 23614 | B1091: VIPULKUMAR DILIPSINH MAHIDA | C1091: 72
...

Sheet Sheet3
A1: P. No. | B1: Scanner
A2: 20114 | B2: 2410 | D2: 21189 | E2: 2410
A3: 20205 | B3: 2410 | D3: 21191 | E3: 2410
A4: 20350 | B4: 2410 | D4: 21202 | E4: 2410
A5: 20373 | B5: 2410 | D5: 21228 | E5: 2410
A6: 20489 | B6: 2410 | D6: 21237 | E6: 2410
A7: 20491 | B7: 2400 | D7: 21279 | E7: 2410
A8: 20505 | B8: 2410 | D8: 21296 | E8: 2410
A9: 20506 | B9: 2410 | D9: 21305 | E9: 2410
A10: 20650 | B10: 2410 | D10: 21306 | E10: 2400
A11: 20652 | B11: 2410 | D11: 21320 | E11: 2410
A12: 20709 | B12: 2410 | D12: 21345 | E12: 2410
A13: 20722 | B13: 2400 | D13: 21349 | E13: 2410
... A26: 21013 | B26: 2410 | D26: 23294 | E26: 2410
A27: 21014 | B27: A3GT20000 | D27: 23363 | E27: 2410
A28: 21052 | B28: 3770 | D28: 23517 | E28: 2400
A29: 21052 | B29: MFP 6525 | D29: 23661 | E29: 2400
A30: 21134 | B30: 2410
A31: 21142 | B31: 2410
A32: 21158 | B32: 2410
A33: 21161 | B33: 2400
A34: 21162 | B34: 2410
A35: 21164 | B35: 2410
A36: 21181 | B36: 2410

Sheet Grade Wise
A1: P Num | B1: Name | C1: Grade | D1: machine_code | E1: dept_name | F1: make | G1: model_name | H1: Scanner | I1: Batch | J1: Change | L1: location
A2: 20652 | B2: MANI R SHARMA | C2: B0 | D2: ODC035 | E2: EXECUTIVE DIRECTOR | F2: DELL | G2: DELL AIO | I2: 10 | L2: DIRECTOR OFFICE | M2: wireless KBD&mouse
A3: 23199 | B3: RAJESH KUMAR AGGARWAL | C3: B0 | D3: ODC034 | E3: OPERATION DIRECTOR | F3: HP | G3: HP ELITE 800G2 | H3: 2400 | I3: 9 | L3: OD'S RESIDENCE
A4: 20652 | B4: MANI R SHARMA | C4: B0 | D4: PGC058 | E4: EXECUTIVE DIRECTOR | F4: HP | G4: HP ELITE 800G1 | H4: =VLOOKUP(A4,Sheet3!A3:B65,2,FALSE) -> 2410 | I4: 8 | L4: GM(PRODN.) OFFICE
A5: 21672 | B5: NIROD KUMAR SAHOO | C5: C0 | D5: V1C037 | E5: HR-ADMINISTRATION | F5: ACER | G5: ACER VERITON Q170 | H5: 2410 | I5: 11 | L5: GM HR OFFICE
A6: 20506 | B6: RAJESH M CHOPDE | C6: C0 | D6: PRC074 | E6: PROCESS GROUP | F6: HP | G6: HP ELITE 800G1 | H6: =VLOOKUP(A6,Sheet3!A8:B70,2,FALSE) -> 2410 | I6: 8 | L6: SM/CM (PROCESS)
A7: 21004 | B7: KANJIBHAI M PATEL | C7: C0 | D7: MSC382 | E7: MECHANICAL | F7: HP | G7: HP ELITE 800G1 | I7: 8 | L7: AGM(MECH) OFFICE
A8: 21008 | B8: APURBA KUMAR B NAYAK | C8: C0 | D8: MEC068 | E8: MECHANICAL | F8: HP | G8: HP ELITE 800G1 | H8: 2410 | I8: 8 | L8: GM(M) OFFICE
A9: 22391 | B9: ANIL KUMAR SINGAL | C9: C0 | D9: FAC189 | E9: FINANCE & ACCOUNTS | F9: HP | G9: HP ELITE 800G1 | I9: 8 | L9: GM(F&A) OFFICE | M9: gpr
A10: 21011 | B10: NAWAL KISHORE GUPTA | C10: C0 | D10: PCC146 | E10: PROCESS GROUP | F10: HCL | G10: HCL INFINITI A390 TRU | H10: 2410 | I10: 7 | J10: 12 | L10: GM(T)'S OFFICE | M10: GS Labana
A11: 20650 | B11: AMAL KUMAR DAS | C11: C0 | D11: MAC032 | E11: PRODUCTION | F11: ACER | G11: ACER VERITON M-200 H57 | H11: =VLOOKUP(A11,Sheet3!A2:B64,2,FALSE) -> 2410 | I11: 5 | J11: 12 | L11: TECHNICAL BLOCK
A12: 21164 | B12: VINOD KUMAR SINGH | C12: C0 | D12: MUC043 | E12: MECHANICAL | F12: ACER | G12: ACER VERITON M-200 H57 | H12: 2410 | I12: 5 | J12: 12 | L12: MAINT BLOCK
A13: 21672 | B13: NIROD KUMAR SAHOO | C13: C0 | D13: IGC023 | E13: HR-ADMINISTRATION | F13: HP | G13: HP DX2480 | I13: 4 | L13: GM (HR) PA'S OFFICE
A14: 21006 | B14: GODAVARTHY SRINIVAS | C14: D0 | D14: V1C019 | E14: PURCHASE | F14: ACER | G14: ACER VERITON Q170 | I14: 11 | L14: AGM(COMM) OFFICE
A15: 21009 | B15: KANDALAM SRIHARI | C15: D0 | D15: PJC085 | E15: PROJECT GROUP | F15: HP | G15: HP ELITE 800G2 | H15: 2410 | I15: 9 | L15: AGM/GM (PROJECT) OFFICE
A16: 21306 | B16: SRIMOY BANERJEE | C16: D0 | D16: PGC060 | E16: PGR-AMMONIA | F16: HP | G16: HP ELITE 800G2 | H16: 2400 | I16: 9 | L16: AGM/GM PRODN OFFICE
A17: 21355 | B17: JATINDER SONDHI | C17: D0 | D17: NDC032 | E17: NDT LABORATORY | F17: HP | G17: HP ELITE 800G2 | I17: 9 | L17: NDT
A18: 21045 | B18: PIYUSH S GANDHI | C18: D0 | D18: SPC096 | E18: INSTRUMENT | F18: HP | G18: HP ELITE 800G2 | I18: 9 | L18: MAINTENANCE BLOCK | M18: issued 27/04/17
A19: 21134 | B19: JAGDISH J DALWADI | C19: D0 | D19: SPC092 | E19: INSTRUMENT | F19: HP | G19: HP ELITE 800G2 | H19: 2410 | I19: 9 | L19: MAINT. BLOCK
A20: 20505 | B20: VENKATESVARULU C | C20: D0 | D20: ELC061 | E20: ELECTRICAL | F20: HP | G20: HP ELITE 800G2 | H20: =VLOOKUP(A20,Sheet3!A7:B69,2,FALSE) -> 2410 | I20: 9 | L20: AGM/GM (ELECTRICAL) OFFICE
A21: 21002 | B21: HIMANSHU B TRIVEDI | C21: D0 | D21: ELC060 | E21: ELECTRICAL | F21: HP | G21: HP ELITE 800G2 | H21: 2410 | I21: 9 | L21: AGM/GM (ELECTRICAL) OFFICE
A22: 21006 | B22: GODAVARTHY SRINIVAS | C22: D0 | D22: STC074 | E22: STORES | F22: HP | G22: HP ELITE 800G1 | H22: 2410 | I22: 8 | L22: AGM/GM OFFICE
A23: 20932 | B23: JAYARAJAN K | C23: D0 | D23: ODC033 | E23: PRODN-POWER | F23: HP | G23: HP ELITE 800G1 | H23: 2410 | I23: 8 | L23: AGM/GM OFFICE | M23: HP G2 PPC033 replaced
A24: 21576 | B24: BHOOPESH SHISHODIA | C24: D0 | D24: PJC084 | E24: MECH-OFFSITE | F24: HP | G24: HP ELITE 800G1 | I24: 8 | L24: DM PLANT | M24: BMitra
A25: 21044 | B25: SATINDER SINGH JOHAR | C25: D0 | D25: MSC384 | E25: HR-ADMINISTRATION | F25: HP | G25: HP ELITE 800G1 | I25: 8 | L25: DGM/AGM HR OFFICE
A26: 21585 | B26: SWADHEEN KUMAR MAHAPATRA | C26: D0 | D26: MSC383 | E26: FIRE & SAFETY | F26: HP | G26: HP ELITE 800G1 | I26: 8 | L26: TECH. BLOCK (ENV. LAB)
A27: 21052 | B27: AMARJIT SINGH | C27: D0 | D27: TCC088 | E27: TRAINING CENTRE | F27: HCL | G27: HCL INFINITI A390 TRU | H27: 3770, MFP6525 | I27: 7 | J27: 12 | L27: AGM OFFICE
A28: 21007 | B28: RAJIVE LOCHAN SHUKLA | C28: D0 | D28: FSC037 | E28: PURCHASE | F28: HCL | G28: HCL INFINITI A390 TRU | H28: 2410 | I28: 7 | J28: 12 | L28: AGM/GM OFFICE
A29: 21593 | B29: UPENDRA KUMAR | C29: D0 | D29: PCC145 | E29: PRODN-PHP | F29: HCL | G29: HCL INFINITI A390 TRU | H29: 2400 | I29: 7 | J29: 12 | L29: PHP - FIRST FLOOR
A30: 20933 | B30: SYED RAFI AHMED | C30: D0 | D30: MBC018 | E30: PRODUCTION | F30: HP | G30: HP ELITE 8200 | I30: 6 | J30: 12 | L30: TECH BLOCK
A31: 21699 | B31: ASHESH K PATEL | C31: D0 | D31: MAC035 | E31: MECH-AMMONIA | F31: HP | G31: HP ELITE 8200 | I31: 6 | J31: 12 | L31: MAINT BLOCK
A32: 21592 | B32: SHANTILAL TULSHIBHAI MAKWANA | C32: D0 | D32: SPC033 | E32: TRANSPORTATION | F32: ACER | G32: ACER VERITON M-200 H57 | H32: 2410 | I32: 5 | J32: 12 | L32: AGM/CM OFFICE
A33: 21404 | B33: SHRAVAN KUMAR | C33: D0 | D33: MAC033 | E33: PROJECT GROUP | F33: ACER | G33: ACER VERITON M-200 H57 | H33: 2400 | I33: 5 | J33: 12 | L33: TECH BLOCK
A34: 21579 | B34: ANIL P DESAI | C34: D0 | D34: GRC034 | E34: PRODN-UREA-I | F34: ACER | G34: ACER VERITON M-200 H57 | I34: 5 | J34: 12 | L34: UREA-I PRODN OFFICE
A35: 21441 | B35: PRAVENDRA SINGH | C35: D0 | D35: PPC032 | E35: PRODN-PHP | F35: ACER | G35: ACER VERITON M-200 H57 | H35: 2410 | I35: 5 | J35: 12 | L35: PHP
A36: 21161 | B36: JAGDISH PRASAD VERMA | C36: D0 | D36: POC027 | E36: PRODN-OFFSITE | F36: ACER | G36: ACER VERITON M-200 H57 | H36: 2400 | I36: 5 | J36: 12 | L36: OFFSITE
A37: 21575 | B37: VINAYKUMAR SINGH | C37: D0 | D37: A2C008 | E37: PRODN-AMMONIA-II | F37: ACER | G37: ACER VERITON M-200 H57 | I37: 5 | J37: 12 | L37: AMMONIA-II
A38: 21349 | B38: RADHESH MOHAN MALLYA | C38: D0 | D38: A1C008 | E38: PRODN-AMMONIA-I | F38: ACER | G38: ACER VERITON M-200 H57 | H38: 2410 | I38: 5 | J38: 12 | L38: AMMONIA-1
A39: 21279 | B39: DILIP KUMAR MANDAL | C39: D0 | D39: PRC067 | E39: PROCESS GROUP | F39: ACER | G39: ACER VERITON M-200 H57 | H39: 2410 | I39: 5 | J39: 12 | L39: TECH BLOCK
A40: 21320 | B40: AVINASH M BHALERAO | C40: D0 | D40: MSC311 | E40: MS-MANAGEMENT SERVICES | F40: ACER | G40: ACER VERITON M-200 H57 | H40: 2410 | I40: 5 | J40: 12 | L40: CM/DGM MS OFFICE
...

Sheet Sheet5
C1: Use | D1: Non Use | G1: Office
A2: 1 | B2: IBM THINK CENTRE - 3.2 GHZ (Core - CRT) | C2: 4 | D2: 2 | E2: Windows XP | F2: 38596 | G2: 2003
A3: 2 | B3: ACER POWER 945G (P4 CRT) | C3: 69 | D3: 74 | E3: Windows XP | F3: 38930 | G3: 2003
A4: 3 | B4: WIPRO SUPER GENIOUS (P4 CRT) | C4: 70 | E4: Windows XP | F4: 39142 | G4: 2003
A5: 4 | B5: HP DX2480 | C5: 50 | E5: Windows XP | F5: 40057 | G5: 2007
A6: 5 | B6: ACER VERITON M-200 H57 | C6: 85 | E6: Windows 7 | F6: 40513 | G6: 2010
A7: 6 | B7: HP ELITE 8200 | C7: 50 | E7: Windows 7 | F7: 41030 | G7: 2010
A8: 7 | B8: HCL INFINITI A390 TRU | C8: 49 | E8: Windows 7 | F8: 41487 | G8: 2013
A9: 8 | B9: HP ELITE 800G1 | C9: 50 | E9: Windows 8 | F9: 42156 | G9: 2013
A10: 9 | B10: HP ELITE 800G2 | C10: 50 | E10: Windows 8 | F10: 42491 | G10: 2016
A11: 10 | B11: Dell AIO | C11: 1 | E11: Win 10
A12: 11 | B12: Acer Veriton Q170 M-200 i5 6500 6th Gen; 4GB RAM; 1000 + 500 GB HDD | C12: 50 | E12: Win 10 | F12: 42917 | G12: 2016
C14: =SUM(C2:C13) -> 528 | D14: =SUM(D2:D13) -> 76
D15: =SUM(C14:D14) -> 604
B17: ACER 6100 | C17: 2
B18: CORE 2 DUO 2.93 GHZ | C18: 1
B19: DUAL CORE 2.7 GHZ | C19: 6
B20: HCL INFINITE 2.0 GHZ | C20: 1
B21: HP COMPAQ DX7380 | C21: 1
B22: INSPIRON D06S | C22: 2
B23: NET VISTA PIV 1.4GHZ | C23: 4
B24: PENTIUM IV 1.5 MHZ | C24: 1
B25: PENTIUM IV 2.20 GHZ | C25: 1
B26: PENTIUM IV 3.2 GHZ | C26: 2
B27: ZEBRONICS | C27: 1
B34: Windows XP | C34: =SUM(C2:C5) -> 193 | D34: =SUM(D2:D3) -> 76 | E34: =SUM(C34:D34) -> 269
B35: Windows 7 | C35: 184 | E35: =SUM(C35:D35) -> 184
B36: Windows 8 | C36: 100 | E36: =SUM(C36:D36) -> 100
B37: Windows 10 | C37: 51 | E37: =SUM(C37:D37) -> 51
C38: =SUM(C34:C37) -> 528 | D38: =SUM(D34:D37) -> 76 | E38: =SUM(C38:D38) -> 604
B41: Office 2003 | C41: 143 | D41: 76 | E41: =SUM(C41:D41) -> 219
B42: Office 2007 | C42: 50 | E42: =SUM(C42:D42) -> 50
B43: Office 2010 | C43: 135 | E43: =SUM(C43:D43) -> 135
B44: Office 2013 | C44: 99 | E44: =SUM(C44:D44) -> 99
B45: Office 2016 | C45: 101 | E45: =SUM(C45:D45) -> 101
C46: =SUM(C41:C45) -> 528 | D46: =SUM(D41:D45) -> 76 | E46: =SUM(E41:E45) -> 604
B49: HAEP
B50: Windows XP | C50: 6
B51: Windows 7 | C51: 15
B52: Windows 8
...
